2021-09-26 16:35:55,871 ERROR libqtile core.py:_xpoll():L321 Shutting down due to X connection error XCB_CONN_ERROR (1)
Traceback (most recent call last):
  File "/usr/lib/python3.9/site-packages/libqtile/backend/x11/core.py", line 283, in _xpoll
    event = self.conn.conn.poll_for_event()
  File "/usr/lib/python3.9/site-packages/xcffib/__init__.py", line 569, in wrapper
    self.invalid()
  File "/usr/lib/python3.9/site-packages/xcffib/__init__.py", line 559, in invalid
    raise ConnectionException(err)
xcffib.ConnectionException: xcb connection errors because of socket, pipe and other stream errors.
2021-09-26 16:35:55,872 ERROR libqtile core.py:get_interesting_pid():L799 Got an exception in getting the window pid
Traceback (most recent call last):
  File "/usr/lib/python3.9/site-packages/libqtile/backend/x11/core.py", line 283, in _xpoll
    event = self.conn.conn.poll_for_event()
  File "/usr/lib/python3.9/site-packages/xcffib/__init__.py", line 569, in wrapper
    self.invalid()
  File "/usr/lib/python3.9/site-packages/xcffib/__init__.py", line 559, in invalid
    raise ConnectionException(err)
xcffib.ConnectionException: xcb connection errors because of socket, pipe and other stream errors.

During handling of the above exception, another exception occurred:

Traceback (most recent call last):
  File "/usr/lib/python3.9/site-packages/libqtile/backend/x11/core.py", line 797, in get_interesting_pid
    return win.window.get_net_wm_pid()
  File "/usr/lib/python3.9/site-packages/libqtile/backend/x11/window.py", line 284, in get_net_wm_pid
    r = self.get_property("_NET_WM_PID", unpack=int)
  File "/usr/lib/python3.9/site-packages/libqtile/backend/x11/window.py", line 377, in get_property
    r = self.conn.conn.core.GetProperty(
  File "/usr/lib/python3.9/site-packages/xcffib/xproto.py", line 2720, in GetProperty
    return self.send_request(20, buf, GetPropertyCookie, is_checked=is_checked)
  File "/usr/lib/python3.9/site-packages/xcffib/__init__.py", line 391, in send_request
    seq = self.conn.send_request(flags, xcb_parts + 2, xcb_req)
  File "/usr/lib/python3.9/site-packages/xcffib/__init__.py", line 569, in wrapper
    self.invalid()
  File "/usr/lib/python3.9/site-packages/xcffib/__init__.py", line 559, in invalid
    raise ConnectionException(err)
xcffib.ConnectionException: xcb connection errors because of socket, pipe and other stream errors.
2021-09-26 16:35:55,873 ERROR libqtile core.py:get_interesting_pid():L799 Got an exception in getting the window pid
Traceback (most recent call last):
  File "/usr/lib/python3.9/site-packages/libqtile/backend/x11/core.py", line 797, in get_interesting_pid
    return win.window.get_net_wm_pid()
  File "/usr/lib/python3.9/site-packages/libqtile/backend/x11/window.py", line 284, in get_net_wm_pid
    r = self.get_property("_NET_WM_PID", unpack=int)
  File "/usr/lib/python3.9/site-packages/libqtile/backend/x11/window.py", line 377, in get_property
    r = self.conn.conn.core.GetProperty(
  File "/usr/lib/python3.9/site-packages/xcffib/xproto.py", line 2720, in GetProperty
    return self.send_request(20, buf, GetPropertyCookie, is_checked=is_checked)
  File "/usr/lib/python3.9/site-packages/xcffib/__init__.py", line 391, in send_request
    seq = self.conn.send_request(flags, xcb_parts + 2, xcb_req)
  File "/usr/lib/python3.9/site-packages/xcffib/__init__.py", line 569, in wrapper
    self.invalid()
  File "/usr/lib/python3.9/site-packages/xcffib/__init__.py", line 559, in invalid
    raise ConnectionException(err)
xcffib.ConnectionException: xcb connection errors because of socket, pipe and other stream errors.
2021-09-26 16:35:55,873 ERROR libqtile core.py:get_interesting_pid():L799 Got an exception in getting the window pid
Traceback (most recent call last):
  File "/usr/lib/python3.9/site-packages/libqtile/backend/x11/core.py", line 797, in get_interesting_pid
    return win.window.get_net_wm_pid()
  File "/usr/lib/python3.9/site-packages/libqtile/backend/x11/window.py", line 284, in get_net_wm_pid
    r = self.get_property("_NET_WM_PID", unpack=int)
  File "/usr/lib/python3.9/site-packages/libqtile/backend/x11/window.py", line 377, in get_property
    r = self.conn.conn.core.GetProperty(
  File "/usr/lib/python3.9/site-packages/xcffib/xproto.py", line 2720, in GetProperty
    return self.send_request(20, buf, GetPropertyCookie, is_checked=is_checked)
  File "/usr/lib/python3.9/site-packages/xcffib/__init__.py", line 391, in send_request
    seq = self.conn.send_request(flags, xcb_parts + 2, xcb_req)
  File "/usr/lib/python3.9/site-packages/xcffib/__init__.py", line 569, in wrapper
    self.invalid()
  File "/usr/lib/python3.9/site-packages/xcffib/__init__.py", line 559, in invalid
    raise ConnectionException(err)
xcffib.ConnectionException: xcb connection errors because of socket, pipe and other stream errors.
2021-09-26 16:35:55,874 ERROR libqtile start.py:start():L91 Qtile crashed
Traceback (most recent call last):
  File "/usr/lib/python3.9/site-packages/xcffib/__init__.py", line 571, in wrapper
    return f(*args)
  File "/usr/lib/python3.9/site-packages/xcffib/__init__.py", line 681, in request_check
    self._process_error(err)
  File "/usr/lib/python3.9/site-packages/xcffib/__init__.py", line 645, in _process_error
    self.invalid()
  File "/usr/lib/python3.9/site-packages/xcffib/__init__.py", line 559, in invalid
    raise ConnectionException(err)
xcffib.ConnectionException: xcb connection errors because of socket, pipe and other stream errors.

During handling of the above exception, another exception occurred:

Traceback (most recent call last):
  File "/usr/lib/python3.9/site-packages/libqtile/scripts/start.py", line 89, in start
    q.loop()
  File "/usr/lib/python3.9/site-packages/libqtile/core/manager.py", line 210, in loop
    asyncio.run(self.async_loop())
  File "/usr/lib/python3.9/asyncio/runners.py", line 44, in run
    return loop.run_until_complete(main)
  File "/usr/lib/python3.9/asyncio/base_events.py", line 642, in run_until_complete
    return future.result()
  File "/usr/lib/python3.9/site-packages/libqtile/core/manager.py", line 234, in async_loop
    self.finalize()
  File "/usr/lib/python3.9/site-packages/libqtile/core/manager.py", line 272, in finalize
    self.core.finalize()
  File "/usr/lib/python3.9/site-packages/libqtile/backend/x11/core.py", line 172, in finalize
    self.conn.conn.core.DeletePropertyChecked(
  File "/usr/lib/python3.9/site-packages/xcffib/__init__.py", line 339, in check
    self.conn.request_check(self.sequence)
  File "/usr/lib/python3.9/site-packages/xcffib/__init__.py", line 573, in wrapper
    self.invalid()
  File "/usr/lib/python3.9/site-packages/xcffib/__init__.py", line 559, in invalid
    raise ConnectionException(err)
xcffib.ConnectionException: xcb connection errors because of socket, pipe and other stream errors.
2021-09-26 16:35:55,875 WARNING libqtile lifecycle.py:_atexit():L38 Qtile will now terminate
